<?xml version='1.0' encoding='utf-8'?>
<robot name="panda">
  
  <link name="panda_link0">
    <visual>
      <geometry>
        <mesh filename="package://franka_description/meshes/visual/link0.dae" />
      </geometry>
    </visual>
  </link>
  <link name="panda_link1">
    <visual>
      <geometry>
        <mesh filename="package://franka_description/meshes/visual/link1.dae" />
      </geometry>
    </visual>
  </link>
  
  
  <joint name="panda_joint1" type="revolute">
    <origin rpy="1.443060036170693e-06 -1.1141116109698583e-08 4.155029228558349e-17" xyz="-4.718650895518294e-17 1.8269338078033916e-17 0.3330000000000001" />
    <parent link="panda_link0" />
    <child link="panda_link1" />
    <axis xyz="0 0 1" />
    <limit effort="87.0" lower="-2.8973" upper="2.8973" velocity="2.175" />
    <safety_controller k_position="100.0" k_velocity="40.0" soft_lower_limit="-2.8973" soft_upper_limit="2.8973" />
  </joint>
  
  <link name="panda_link2">
    <visual>
      <geometry>
        <mesh filename="package://franka_description/meshes/visual/link2.dae" />
      </geometry>
    </visual>
  </link>
  
  <joint name="panda_joint2" type="revolute">
    <origin rpy="-1.569224519569118 0.00025953051430076826 -1.231885684286843e-12" xyz="-0.00030272394705944304 0.0001314392452688879 9.108197157677059e-17" />
    <parent link="panda_link1" />
    <child link="panda_link2" />
    <axis xyz="0 0 1" />
    <limit effort="87.0" lower="-1.7628" upper="1.7628" velocity="2.175" />
    <safety_controller k_position="100.0" k_velocity="40.0" soft_lower_limit="-1.7628" soft_upper_limit="1.7628" />
  </joint>
  
  <link name="panda_link3">
    <visual>
      <geometry>
        <mesh filename="package://franka_description/meshes/visual/link3.dae" />
      </geometry>
    </visual>
  </link>
  
  <joint name="panda_joint3" type="revolute">
    <origin rpy="1.5699519202736834 0.0001772122188351117 0.000170842570736644" xyz="0.0002806590580034444 -0.31598109159365023 0.0001314389571123128" />
    <parent link="panda_link2" />
    <child link="panda_link3" />
    <axis xyz="0 0 1" />
    <limit effort="87.0" lower="-2.8973" upper="2.8973" velocity="2.175" />
    <safety_controller k_position="100.0" k_velocity="40.0" soft_lower_limit="-2.8973" soft_upper_limit="2.8973" />
  </joint>
  
  <link name="panda_link4">
    <visual>
      <geometry>
        <mesh filename="package://franka_description/meshes/visual/link4.dae" />
      </geometry>
    </visual>
  </link>
  
  <joint name="panda_joint4" type="revolute">
    <origin rpy="1.570329238798954 0.003634167542939902 -0.0001726478966157702" xyz="0.0821772511639403 -5.357729068531642e-05 -1.874942118968558e-05" />
    <parent link="panda_link3" />
    <child link="panda_link4" />
    <axis xyz="0 0 1" />
    <limit effort="87.0" lower="-3.0718" upper="-0.0698" velocity="2.175" />
    <safety_controller k_position="100.0" k_velocity="40.0" soft_lower_limit="-3.0718" soft_upper_limit="-0.0698" />
  </joint>
  
  <link name="panda_link5">
    <visual>
      <geometry>
        <mesh filename="package://franka_description/meshes/visual/link5.dae" />
      </geometry>
    </visual>
  </link>
  
  <joint name="panda_joint5" type="revolute">
    <origin rpy="-1.5704333701293198 0.0014558181290433314 -0.0032984710877434252" xyz="-0.08166184278074558 0.38416878967114904 5.362369925985596e-05" />
    <parent link="panda_link4" />
    <child link="panda_link5" />
    <axis xyz="0 0 1" />
    <limit effort="12.0" lower="-2.8973" upper="2.8973" velocity="2.61" />
    <safety_controller k_position="100.0" k_velocity="40.0" soft_lower_limit="-2.8973" soft_upper_limit="2.8973" />
  </joint>
  
  <link name="panda_link6">
    <visual>
      <geometry>
        <mesh filename="package://franka_description/meshes/visual/link6.dae" />
      </geometry>
    </visual>
  </link>
  
  <joint name="panda_joint6" type="revolute">
    <origin rpy="1.567932496342769 0.00015208320336658598 0.0014546210159514484" xyz="-4.8597064810259795e-05 0.0004293227821836948 0.00017157328439707152" />
    <parent link="panda_link5" />
    <child link="panda_link6" />
    <axis xyz="0 0 1" />
    <limit effort="12.0" lower="-0.0175" upper="3.7525" velocity="2.61" />
    <safety_controller k_position="100.0" k_velocity="40.0" soft_lower_limit="-0.0175" soft_upper_limit="3.7525" />
  </joint>
  
  <link name="panda_link7">
    <visual>
      <geometry>
        <mesh filename="package://franka_description/meshes/visual/link7.dae" />
      </geometry>
    </visual>
  </link>
  
  <joint name="panda_joint7" type="revolute">
    <origin rpy="1.5709182503980177 -2.2182325530324566e-08 -6.317227097718112e-05" xyz="0.08770649743939672 -0.0009630206421383316 -0.00042889992127301946" />
    <parent link="panda_link6" />
    <child link="panda_link7" />
    <axis xyz="0 0 1" />
    <limit effort="12.0" lower="-2.8973" upper="2.8973" velocity="2.61" />
    <safety_controller k_position="100.0" k_velocity="40.0" soft_lower_limit="-2.8973" soft_upper_limit="2.8973" />
  </joint>
  <link name="panda_link8" />
  <joint name="panda_joint8" type="fixed">
    <origin rpy="0 0 0" xyz="0 0 0.107" />
    <parent link="panda_link7" />
    <child link="panda_link8" />
  </joint>
  <joint name="panda_hand_joint" type="fixed">
    <parent link="panda_link8" />
    <child link="panda_hand" />
    <origin rpy="0 0 -0.7853981633974483" xyz="0 0 0" />
  </joint>
  
  <link name="panda_hand">
    <visual>
      <geometry>
        <mesh filename="package://franka_description/meshes/visual/hand.dae" />
      </geometry>
    </visual>
  </link>
  <link name="panda_hand_tcp" />
  <joint name="panda_hand_tcp_joint" type="fixed">
    <origin rpy="0 0 0" xyz="0 0 0.1034" />
    <parent link="panda_hand" />
    <child link="panda_hand_tcp" />
  </joint>
  <link name="ball_link">
    <visual>
      <material name="red">
        <color rgba="1 0 0 1" />
      </material>

      <geometry>
        <sphere radius="0.005" />
      </geometry>
    </visual>
  </link>

  <joint name="ball_joint" type="fixed">
    <origin rpy="0.0 0.0 0.0" xyz="0.0003778447912426314 0.00017972692094397734 0.031091389390698887" />
    <parent link="panda_hand_tcp" />
    <child link="ball_link" />
  </joint>
  <link name="panda_leftfinger">
    <visual>
      <geometry>
        <mesh filename="package://franka_description/meshes/visual/finger.dae" />
      </geometry>
    </visual>
  </link>
  <link name="panda_rightfinger">
    <visual>
      <origin rpy="0 0 3.141592653589793" xyz="0 0 0" />
      <geometry>
        <mesh filename="package://franka_description/meshes/visual/finger.dae" />
      </geometry>
    </visual>
  </link>

    <joint name="panda_finger_joint1" type="prismatic">
    <parent link="panda_hand" />
    <child link="panda_leftfinger" />
    <origin rpy="0 0 0" xyz="0 0 0.0584" />
    <axis xyz="0 1 0" />
    <limit effort="100" lower="0.0" upper="0.04" velocity="0.2" />
    <dynamics damping="0.3" />
  </joint>
  <joint name="panda_finger_joint2" type="prismatic">
    <parent link="panda_hand" />
    <child link="panda_rightfinger" />
    <origin rpy="0 0 0" xyz="0 0 0.0584" />
    <axis xyz="0 -1 0" />
    <limit effort="100" lower="0.0" upper="0.04" velocity="0.2" />
    <mimic joint="panda_finger_joint1" />
    <dynamics damping="0.3" />
  </joint>
</robot>